Workbook

Sheet Resumo
A1: Antevia - Projecao de receitas (v2) - resumo
A2: Modelo em 3 fases: o poder de negociacao com fornecedores e conquistado, nao assumido.
A4: Cenario | B4: Ano 1 | C4: Ano 2 | D4: Ano 3 | E4: Total 3 anos | F4: Viagens | G4: GMV | H4: Economia alunos
A5: Pessimista | B5: =Cenarios!F22 | C5: =Cenarios!F23 | D5: =Cenarios!F24 | E5: =Cenarios!F21 | F5: =Cenarios!E21 | G5: =Cenarios!G21 | H5: =Cenarios!H21
A6: Tendencial | B6: =Cenarios!F44 | C6: =Cenarios!F45 | D6: =Cenarios!F46 | E6: =Cenarios!F43 | F6: =Cenarios!E43 | G6: =Cenarios!G43 | H6: =Cenarios!H43
A7: Otimista | B7: =Cenarios!F66 | C7: =Cenarios!F67 | D7: =Cenarios!F68 | E7: =Cenarios!F65 | F7: =Cenarios!E65 | G7: =Cenarios!G65 | H7: =Cenarios!H65
A10: As tres fases de poder de negociacao
A11: Fase | B11: Como compramos | C11: Ticket | D11: Economia liquida | E11: Retorno | F11: Comissao | G11: R$/viagem
A12: Fase 1 | B12: Apoio da consolidadora - so antecipacao | C12: =Premissas!C26 | D12: =Premissas!C28 | E12: =Premissas!C29 | F12: =Premissas!C22 | G12: =Premissas!C31
A13: Fase 2 | B13: Bloqueios pontuais nas rotas que concentram | C13: =Premissas!D26 | D13: =Premissas!D28 | E13: =Premissas!D29 | F13: =Premissas!D22 | G13: =Premissas!D31
A14: Fase 3 | B14: Convenio proprio | C14: =Premissas!E26 | D14: =Premissas!E28 | E14: =Premissas!E29 | F14: =Premissas!E22 | G14: =Premissas!E31
A17: Sensibilidade - uma variavel por vez, base tendencial
A18: Variavel | B18: Baixo | C18: Base | D18: Alto | E18: Impacto - | F18: Impacto +
A19: Tamanho da turma (30 / 60 alunos) | B19: =Cenarios!$F$43*30/40 | C19: =Cenarios!$F$43 | D19: =Cenarios!$F$43*60/40 | E19: =B19/C19-1 | F19: =D19/C19-1
A20: Adesao (20/30/40% vs 40/55/70%) | B20: 639487 | C20: =Cenarios!$F$43 | D20: 1137087 | E20: =B20/C20-1 | F20: =D20/C20-1
A21: Ritmo de contratacao de turmas (+/-30%) | B21: =Cenarios!$F$43*0.7 | C21: =Cenarios!$F$43 | D21: =Cenarios!$F$43*1.3 | E21: =B21/C21-1 | F21: =D21/C21-1
A22: Comissao (uma faixa abaixo / acima) | B22: 824602 | C22: =Cenarios!$F$43 | D22: 1236730 | E22: =B22/C22-1 | F22: =D22/C22-1
A23: Taxa de servico (R$ 50 / R$ 150) | B23: 721630 | C23: =Cenarios!$F$43 | D23: 1196830 | E23: =B23/C23-1 | F23: =D23/C23-1
A25: As tres primeiras estao na mesma faixa de importancia. A primeira nunca foi validada.

Sheet Premissas
A1: Antevia - Sprint 4 (v2) - Premissas
A2: Dourado = entrada editavel. Azul claro = derivado por formula. O modelo evolui em 3 fases de poder de negociacao.
A4: ID | B4: Premissa | C4: Valor | D4: Unid. | E4: Origem | F4: Status
A5: P1 | B5: Matriculados em pos-graduacao (Brasil) | C5: 1400000 | D5: alunos | E5: IBGE | F5: Validada
A6: P2 | B6: Fatia em programas executivos presenciais | C6: 0.12 | D6: % | E6: Estimativa | F6: A validar
A7: P3 | B7: Fatia que viaja de outra cidade | C7: 0.25 | D7: % | E7: Entrevistas S1 | F7: A validar
A8: P4 | B8: SAM como fatia do TAM | C8: 0.25 | D8: % | E8: Estimativa | F8: A validar
A9: P5 | B9: ALUNOS POR TURMA | C9: 40 | D9: alunos | E9: Estimativa do grupo | F9: A validar
A10: P6 | B10: Modulos por programa | C10: 12 | D10: modulos | E10: Exemplo da banca | F10: A validar
A11: P7 | B11: Duracao do ciclo da turma | C11: 20 | D11: meses | E11: Persona Ricardo | F11: Validada
A12: P8 | B12: Origens principais por turma | C12: 6 | D12: origens | E12: Velt (5-8) | F12: Calibrada
A13: P15 | B13: Taxa de servico por modulo | C13: 100 | D13: R$ | E13: H6 Sprint 1 | F13: A validar
A14: P21 | B14: Pax minimos p/ tarifa de grupo | C14: 10 | D14: pax | E14: Pratica mercado | F14: A validar
A16: Parametros por fase
A17: Item | B17: Hoje | C17: Fase 1 (ano 1) | D17: Fase 2 (ano 2) | E17: Fase 3 (ano 3)
A18: Aereo ida e volta | B18: 1400 | C18: 1150 | D18: 1080 | E18: 1020
A19: Hotel 2 diarias | B19: 600 | C19: 570 | D19: 530 | E19: 500
A20: Traslado | B20: 200 | C20: 200 | D20: 190 | E20: 180
A21: Adesao da turma (tendencial) | B21: - | C21: 0.3 | D21: 0.45 | E21: 0.6
A22: Comissao media sobre o ticket | B22: - | C22: 0.03 | D22: 0.05 | E22: 0.064
A24: Derivados por fase
A25: Item | B25: Hoje | C25: Fase 1 | D25: Fase 2 | E25: Fase 3
A26: Ticket logistico | B26: =B18+B19+B20 | C26: =C18+C19+C20 | D26: =D18+D19+D20 | E26: =E18+E19+E20
A27: Economia bruta vs hoje | B27: - | C27: =$B$26-C26 | D27: =$B$26-D26 | E27: =$B$26-E26
A28: Economia liquida do aluno | B28: - | C28: =C27-$C$13 | D28: =D27-$C$13 | E28: =E27-$C$13
A29: Retorno sobre a taxa | B29: - | C29: =C28/$C$13 | D29: =D28/$C$13 | E29: =E28/$C$13
A30: Comissao por viagem | B30: - | C30: =C26*C22 | D30: =D26*D22 | E30: =E26*E22
A31: Receita por viagem | B31: - | C31: =$C$13+C30 | D31: =$C$13+D30 | E31: =$C$13+E30
A32: Viagens por aderente/trimestre | B32: - | C32: =$C$10/$C$11*3 | D32: =$C$10/$C$11*3 | E32: =$C$10/$C$11*3

Sheet Cenarios
A1: Cenarios de receita - 12 trimestres, 3 fases de poder de negociacao
A2: O cenario tendencial herda a adesao das Premissas. Pessimista e otimista tem adesao propria por fase.
A4: Pessimista
A5: Adesao por fase | B5: Ano 1 | C5: Ano 2 | D5: Ano 3
A6: Adesao | B6: 0.2 | C6: 0.3 | D6: 0.4
A8: Trim. | B8: Fase | C8: Turmas | D8: Aderentes | E8: Viagens | F8: Receita (R$) | G8: GMV (R$) | H8: Economia alunos (R$)
A9: T1 | B9: 1 | C9: 0 | D9: =C9*Premissas!$C$9*$B$6 | E9: =D9*Premissas!$C$32 | F9: =E9*Premissas!$C$31 | G9: =E9*Premissas!$C$26 | H9: =E9*Premissas!$C$28
A10: T2 | B10: 1 | C10: 1 | D10: =C10*Premissas!$C$9*$B$6 | E10: =D10*Premissas!$C$32 | F10: =E10*Premissas!$C$31 | G10: =E10*Premissas!$C$26 | H10: =E10*Premissas!$C$28
A11: T3 | B11: 1 | C11: 1 | D11: =C11*Premissas!$C$9*$B$6 | E11: =D11*Premissas!$C$32 | F11: =E11*Premissas!$C$31 | G11: =E11*Premissas!$C$26 | H11: =E11*Premissas!$C$28
A12: T4 | B12: 1 | C12: 2 | D12: =C12*Premissas!$C$9*$B$6 | E12: =D12*Premissas!$C$32 | F12: =E12*Premissas!$C$31 | G12: =E12*Premissas!$C$26 | H12: =E12*Premissas!$C$28
A13: T5 | B13: 2 | C13: 3 | D13: =C13*Premissas!$C$9*$C$6 | E13: =D13*Premissas!$D$32 | F13: =E13*Premissas!$D$31 | G13: =E13*Premissas!$D$26 | H13: =E13*Premissas!$D$28
A14: T6 | B14: 2 | C14: 4 | D14: =C14*Premissas!$C$9*$C$6 | E14: =D14*Premissas!$D$32 | F14: =E14*Premissas!$D$31 | G14: =E14*Premissas!$D$26 | H14: =E14*Premissas!$D$28
A15: T7 | B15: 2 | C15: 5 | D15: =C15*Premissas!$C$9*$C$6 | E15: =D15*Premissas!$D$32 | F15: =E15*Premissas!$D$31 | G15: =E15*Premissas!$D$26 | H15: =E15*Premissas!$D$28
A16: T8 | B16: 2 | C16: 6 | D16: =C16*Premissas!$C$9*$C$6 | E16: =D16*Premissas!$D$32 | F16: =E16*Premissas!$D$31 | G16: =E16*Premissas!$D$26 | H16: =E16*Premissas!$D$28
A17: T9 | B17: 3 | C17: 8 | D17: =C17*Premissas!$C$9*$D$6 | E17: =D17*Premissas!$E$32 | F17: =E17*Premissas!$E$31 | G17: =E17*Premissas!$E$26 | H17: =E17*Premissas!$E$28
A18: T10 | B18: 3 | C18: 10 | D18: =C18*Premissas!$C$9*$D$6 | E18: =D18*Premissas!$E$32 | F18: =E18*Premissas!$E$31 | G18: =E18*Premissas!$E$26 | H18: =E18*Premissas!$E$28
A19: T11 | B19: 3 | C19: 12 | D19: =C19*Premissas!$C$9*$D$6 | E19: =D19*Premissas!$E$32 | F19: =E19*Premissas!$E$31 | G19: =E19*Premissas!$E$26 | H19: =E19*Premissas!$E$28
A20: T12 | B20: 3 | C20: 14 | D20: =C20*Premissas!$C$9*$D$6 | E20: =D20*Premissas!$E$32 | F20: =E20*Premissas!$E$31 | G20: =E20*Premissas!$E$26 | H20: =E20*Premissas!$E$28
A21: Total | C21: =SUM(C9:C20) | D21: =SUM(D9:D20) | E21: =SUM(E9:E20) | F21: =SUM(F9:F20) | G21: =SUM(G9:G20) | H21: =SUM(H9:H20)
A22: Ano 1 | F22: =SUM(F9:F12)
A23: Ano 2 | F23: =SUM(F13:F16)
A24: Ano 3 | F24: =SUM(F17:F20)
A26: Tendencial
A27: Adesao por fase | B27: Ano 1 | C27: Ano 2 | D27: Ano 3
A28: Adesao | B28: =Premissas!C21 | C28: =Premissas!D21 | D28: =Premissas!E21
A30: Trim. | B30: Fase | C30: Turmas | D30: Aderentes | E30: Viagens | F30: Receita (R$) | G30: GMV (R$) | H30: Economia alunos (R$)
A31: T1 | B31: 1 | C31: 1 | D31: =C31*Premissas!$C$9*$B$28 | E31: =D31*Premissas!$C$32 | F31: =E31*Premissas!$C$31 | G31: =E31*Premissas!$C$26 | H31: =E31*Premissas!$C$28
A32: T2 | B32: 1 | C32: 2 | D32: =C32*Premissas!$C$9*$B$28 | E32: =D32*Premissas!$C$32 | F32: =E32*Premissas!$C$31 | G32: =E32*Premissas!$C$26 | H32: =E32*Premissas!$C$28
A33: T3 | B33: 1 | C33: 3 | D33: =C33*Premissas!$C$9*$B$28 | E33: =D33*Premissas!$C$32 | F33: =E33*Premissas!$C$31 | G33: =E33*Premissas!$C$26 | H33: =E33*Premissas!$C$28
A34: T4 | B34: 1 | C34: 4 | D34: =C34*Premissas!$C$9*$B$28 | E34: =D34*Premissas!$C$32 | F34: =E34*Premissas!$C$31 | G34: =E34*Premissas!$C$26 | H34: =E34*Premissas!$C$28
A35: T5 | B35: 2 | C35: 6 | D35: =C35*Premissas!$C$9*$C$28 | E35: =D35*Premissas!$D$32 | F35: =E35*Premissas!$D$31 | G35: =E35*Premissas!$D$26 | H35: =E35*Premissas!$D$28
A36: T6 | B36: 2 | C36: 8 | D36: =C36*Premissas!$C$9*$C$28 | E36: =D36*Premissas!$D$32 | F36: =E36*Premissas!$D$31 | G36: =E36*Premissas!$D$26 | H36: =E36*Premissas!$D$28
A37: T7 | B37: 2 | C37: 10 | D37: =C37*Premissas!$C$9*$C$28 | E37: =D37*Premissas!$D$32 | F37: =E37*Premissas!$D$31 | G37: =E37*Premissas!$D$26 | H37: =E37*Premissas!$D$28
A38: T8 | B38: 2 | C38: 12 | D38: =C38*Premissas!$C$9*$C$28 | E38: =D38*Premissas!$D$32 | F38: =E38*Premissas!$D$31 | G38: =E38*Premissas!$D$26 | H38: =E38*Premissas!$D$28
A39: T9 | B39: 3 | C39: 15 | D39: =C39*Premissas!$C$9*$D$28 | E39: =D39*Premissas!$E$32 | F39: =E39*Premissas!$E$31 | G39: =E39*Premissas!$E$26 | H39: =E39*Premissas!$E$28
A40: T10 | B40: 3 | C40: 18 | D40: =C40*Premissas!$C$9*$D$28 | E40: =D40*Premissas!$E$32 | F40: =E40*Premissas!$E$31 | G40: =E40*Premissas!$E$26 | H40: =E40*Premissas!$E$28
A41: T11 | B41: 3 | C41: 21 | D41: =C41*Premissas!$C$9*$D$28 | E41: =D41*Premissas!$E$32 | F41: =E41*Premissas!$E$31 | G41: =E41*Premissas!$E$26 | H41: =E41*Premissas!$E$28
A42: T12 | B42: 3 | C42: 24 | D42: =C42*Premissas!$C$9*$D$28 | E42: =D42*Premissas!$E$32 | F42: =E42*Premissas!$E$31 | G42: =E42*Premissas!$E$26 | H42: =E42*Premissas!$E$28
A43: Total | C43: =SUM(C31:C42) | D43: =SUM(D31:D42) | E43: =SUM(E31:E42) | F43: =SUM(F31:F42) | G43: =SUM(G31:G42) | H43: =SUM(H31:H42)
A44: Ano 1 | F44: =SUM(F31:F34)
...

Sheet Tarifa de grupo
A1: Uma turma isolada forma tarifa de grupo?
A2: Pax por rota = turma x adesao / origens. Precisa atingir P21 (10 pax) para haver tarifa de grupo.
A4: Turma | B4: Adesao | C4: Origens | D4: Pax por rota | E4: Forma grupo? | F4: Turmas necessarias no mesmo campus/data
A5: 30 | B5: 0.3 | C5: 5 | D5: =A5*B5/C5 | E5: =IF(D5>=Premissas!$C$14,"SIM","nao") | F5: =ROUNDUP(Premissas!$C$14/D5,0)
A6: 30 | B6: 0.3 | C6: 8 | D6: =A6*B6/C6 | E6: =IF(D6>=Premissas!$C$14,"SIM","nao") | F6: =ROUNDUP(Premissas!$C$14/D6,0)
A7: 30 | B7: 0.6 | C7: 5 | D7: =A7*B7/C7 | E7: =IF(D7>=Premissas!$C$14,"SIM","nao") | F7: =ROUNDUP(Premissas!$C$14/D7,0)
A8: 30 | B8: 0.6 | C8: 8 | D8: =A8*B8/C8 | E8: =IF(D8>=Premissas!$C$14,"SIM","nao") | F8: =ROUNDUP(Premissas!$C$14/D8,0)
A9: 40 | B9: 0.3 | C9: 5 | D9: =A9*B9/C9 | E9: =IF(D9>=Premissas!$C$14,"SIM","nao") | F9: =ROUNDUP(Premissas!$C$14/D9,0)
A10: 40 | B10: 0.3 | C10: 8 | D10: =A10*B10/C10 | E10: =IF(D10>=Premissas!$C$14,"SIM","nao") | F10: =ROUNDUP(Premissas!$C$14/D10,0)
A11: 40 | B11: 0.6 | C11: 5 | D11: =A11*B11/C11 | E11: =IF(D11>=Premissas!$C$14,"SIM","nao") | F11: =ROUNDUP(Premissas!$C$14/D11,0)
A12: 40 | B12: 0.6 | C12: 8 | D12: =A12*B12/C12 | E12: =IF(D12>=Premissas!$C$14,"SIM","nao") | F12: =ROUNDUP(Premissas!$C$14/D12,0)
A13: 60 | B13: 0.3 | C13: 5 | D13: =A13*B13/C13 | E13: =IF(D13>=Premissas!$C$14,"SIM","nao") | F13: =ROUNDUP(Premissas!$C$14/D13,0)
A14: 60 | B14: 0.3 | C14: 8 | D14: =A14*B14/C14 | E14: =IF(D14>=Premissas!$C$14,"SIM","nao") | F14: =ROUNDUP(Premissas!$C$14/D14,0)
A15: 60 | B15: 0.6 | C15: 5 | D15: =A15*B15/C15 | E15: =IF(D15>=Premissas!$C$14,"SIM","nao") | F15: =ROUNDUP(Premissas!$C$14/D15,0)
A16: 60 | B16: 0.6 | C16: 8 | D16: =A16*B16/C16 | E16: =IF(D16>=Premissas!$C$14,"SIM","nao") | F16: =ROUNDUP(Premissas!$C$14/D16,0)
... A20: 100 | B20: 0.6 | C20: 8 | D20: =A20*B20/C20 | E20: =IF(D20>=Premissas!$C$14,"SIM","nao") | F20: =ROUNDUP(Premissas!$C$14/D20,0)
